Workbook

Sheet Monsters
A1: Severance - Monster Stats
A2: Blue = numbers taken from enemies.py. Black = calculated by formula. Pink rows = bosses.
A4: Name | B4: Dungeon | C4: Rooms | D4: Role | E4: HP | F4: Attack | G4: Defence | H4: XP Reward | I4: Damage Blocked by Defence | J4: Effective HP | K4: Enrage At (HP %) | L4: Enrage Multiplier | M4: Enraged Attack | N4: Special Moves | O4: Status
A5: Mutated Tadpole | B5: Rainforest River | C5: 1 | D5: Add | E5: 25 | F5: 4 | G5: 5 | H5: 5 | I5: =1-100/(100+G5) -> 0.047619048 | J5: =ROUND(E5*(100+G5)/100,0) -> 26 | K5: - | L5: - | M5: =IF(D5="Boss",F5*L5,"-") -> - | N5: - | O5: In game
A6: Mutated Frog | B6: Rainforest River | C6: 2, 3 | D6: Add | E6: 40 | F6: 4 | G6: 10 | H6: 8 | I6: =1-100/(100+G6) -> 0.090909091 | J6: =ROUND(E6*(100+G6)/100,0) -> 44 | K6: - | L6: - | M6: =IF(D6="Boss",F6*L6,"-") -> - | N6: - | O6: In game
A7: Mutated Boar | B7: Rainforest River | C7: 3 | D7: Add | E7: 35 | F7: 12 | G7: 2 | H7: 12 | I7: =1-100/(100+G7) -> 0.019607843 | J7: =ROUND(E7*(100+G7)/100,0) -> 36 | K7: - | L7: - | M7: =IF(D7="Boss",F7*L7,"-") -> - | N7: - | O7: In game
A8: Mutated Cheetah | B8: Rainforest River | C8: 4 (boss) | D8: Boss | E8: 100 | F8: 12 | G8: 5 | H8: 30 | I8: =1-100/(100+G8) -> 0.047619048 | J8: =ROUND(E8*(100+G8)/100,0) -> 105 | K8: 0.25 | L8: 2 | M8: =IF(D8="Boss",F8*L8,"-") -> 24 | N8: Pounce | O8: In game
A9: Security Drone | B9: Derelict Spaceship | C9: 1, 2 | D9: Add | E9: 22 | F9: 5 | G9: 5 | H9: 6 | I9: =1-100/(100+G9) -> 0.047619048 | J9: =ROUND(E9*(100+G9)/100,0) -> 23 | K9: - | L9: - | M9: =IF(D9="Boss",F9*L9,"-") -> - | N9: - | O9: In game
A10: Maintenance Bot | B10: Derelict Spaceship | C10: 2 | D10: Add | E10: 70 | F10: 8 | G10: 15 | H10: 16 | I10: =1-100/(100+G10) -> 0.13043478 | J10: =ROUND(E10*(100+G10)/100,0) -> 81 | K10: - | L10: - | M10: =IF(D10="Boss",F10*L10,"-") -> - | N10: - | O10: In game
A11: Sentry Turret | B11: Derelict Spaceship | C11: 3 | D11: Add | E11: 30 | F11: 9 | G11: 5 | H11: 14 | I11: =1-100/(100+G11) -> 0.047619048 | J11: =ROUND(E11*(100+G11)/100,0) -> 32 | K11: - | L11: - | M11: =IF(D11="Boss",F11*L11,"-") -> - | N11: - | O11: In game
A12: Rogue Overseer | B12: Derelict Spaceship | C12: 4 (boss) | D12: Boss | E12: 120 | F12: 10 | G12: 10 | H12: 45 | I12: =1-100/(100+G12) -> 0.090909091 | J12: =ROUND(E12*(100+G12)/100,0) -> 132 | K12: 0.25 | L12: 1.5 | M12: =IF(D12="Boss",F12*L12,"-") -> 15 | N12: Laser Sweep, Twin Blasters | O12: In game
A13: Rift Wisp | B13: Heart of the Rift | C13: - | D13: Add | E13: 60 | F13: 18 | G13: 10 | H13: 40 | I13: =1-100/(100+G13) -> 0.090909091 | J13: =ROUND(E13*(100+G13)/100,0) -> 66 | K13: - | L13: - | M13: =IF(D13="Boss",F13*L13,"-") -> - | N13: - | O13: Unused (dungeon removed)
A14: Rift Knight | B14: Heart of the Rift | C14: - | D14: Add | E14: 180 | F14: 32 | G14: 40 | H14: 120 | I14: =1-100/(100+G14) -> 0.28571429 | J14: =ROUND(E14*(100+G14)/100,0) -> 252 | K14: - | L14: - | M14: =IF(D14="Boss",F14*L14,"-") -> - | N14: - | O14: Unused (dungeon removed)
A15: Rift Stalker | B15: Heart of the Rift | C15: - | D15: Add | E15: 110 | F15: 35 | G15: 10 | H15: 90 | I15: =1-100/(100+G15) -> 0.090909091 | J15: =ROUND(E15*(100+G15)/100,0) -> 121 | K15: - | L15: - | M15: =IF(D15="Boss",F15*L15,"-") -> - | N15: - | O15: Unused (dungeon removed)
A16: Rift Warden | B16: Heart of the Rift | C16: - | D16: Boss | E16: 450 | F16: 34 | G16: 30 | H16: 300 | I16: =1-100/(100+G16) -> 0.23076923 | J16: =ROUND(E16*(100+G16)/100,0) -> 585 | K16: 0.25 | L16: 1.4 | M16: =IF(D16="Boss",F16*L16,"-") -> 47.6 | N16: Crushing Slam | O16: Unused (dungeon removed)
A17: Hollow Colossus | B17: Heart of the Rift | C17: - | D17: Boss | E17: 900 | F17: 42 | G17: 40 | H17: 600 | I17: =1-100/(100+G17) -> 0.28571429 | J17: =ROUND(E17*(100+G17)/100,0) -> 1260 | K17: 0.3 | L17: 1.5 | M17: =IF(D17="Boss",F17*L17,"-") -> 63 | N17: Cataclysm, Rending Claws, Tremor | O17: Unused (dungeon removed)
A19: Notes
A20: Damage Blocked = 1 - 100/(100 + Defence). Same formula as take_damage() in character.py.
A21: Effective HP = HP x (100 + Defence)/100, i.e. how much raw damage it takes to kill it.
A22: Enrage: when a boss drops to 'Enrage At' of its max HP, its attack is multiplied by 'Enrage Multiplier' (once).
A23: Bosses use the default enrage_at of 25% from enemy.py unless enemies.py sets it (Hollow Colossus = 30%).

Sheet Classes
A1: Severance - Player Classes
A2: Blue = numbers from classes.py / player.py. Black = calculated. Change a blue number and everything below updates.
A4: Class Stats
A5: Class | B5: Pillar | C5: Base HP | D5: Base Attack | E5: Base Defence | F5: HP per Level | G5: Attack per Level | H5: Defence per Level | I5: Defend Strength (damage ÷) | J5: Defend Blocks % | K5: Max Mana | L5: Mana Regen | M5: Max Level | N5: Status
A6: Paladin | B6: Religion | C6: 120 | D6: 10 | E6: 6 | F6: 12 | G6: 1 | H6: 3 | I6: 3 | J6: =1-1/I6 -> 0.66666667 | K6: 0 | L6: 0 | M6: 20 | N6: In game
A7: Sorcerer | B7: Science? (TBD) | C7: - | D7: - | E7: - | F7: - | G7: - | H7: - | I7: - | J7: - | K7: - | L7: - | M7: - | N7: Planned (mana class)
A9: Paladin Abilities
A10: Ability | B10: Key | C10: Type | D10: Unlock Level | E10: Power | F10: Cooldown (turns) | G10: Target | H10: Mana Cost | I10: Lifesteal % | J10: Attack at Unlock | K10: Raw Effect at Unlock | L10: Raw Effect at Lv 20 | M10: What It Does
A11: Shield Bash | B11: S | C11: Damage | D11: 1 | E11: 1.3 | F11: 2 | G11: One enemy | H11: 0 | I11: - | J11: =INDEX($C$25:$C$44,D11) -> 10 | K11: =ROUND(J11*E11,0) -> 13 | L11: =ROUND($C$44*E11,0) -> 38 | M11: Hits one enemy for 1.3x attack
A12: Holy Strike | B12: H | C12: Damage | D12: 1 | E12: 2 | F12: 4 | G12: One enemy | H12: 0 | I12: - | J12: =INDEX($C$25:$C$44,D12) -> 10 | K12: =ROUND(J12*E12,0) -> 20 | L12: =ROUND($C$44*E12,0) -> 58 | M12: Big single hit, 2x attack
A13: Holy Ground | B13: G | C13: Damage (AOE) | D13: 2 | E13: 1.3 | F13: 3 | G13: All enemies | H13: 0 | I13: - | J13: =INDEX($C$25:$C$44,D13) -> 11 | K13: =ROUND(J13*E13,0) -> 14 | L13: =ROUND($C$44*E13,0) -> 38 | M13: Hits every enemy for 1.3x attack
A14: Lay on Hands | B14: L | C14: Heal | D14: 5 | E14: 0.25 | F14: 7 | G14: Self | H14: 0 | I14: - | J14: =INDEX($C$25:$C$44,D14) -> 14 | K14: =ROUND(INDEX($B$25:$B$44,D14)*E14,0)&" HP" -> 42 HP | L14: =ROUND($B$44*E14,0)&" HP" -> 87 HP | M14: Heals 25% of max HP
A15: Divine Aegis | B15: E | C15: Block | D15: 9 | E15: 0 | F15: 6 | G15: Self | H15: 0 | I15: - | J15: =INDEX($C$25:$C$44,D15) -> 18 | K15: All | L15: All | M15: Blocks ALL damage for the rest of the turn
A16: Radiant Slash | B16: R | C16: Lifesteal | D16: 13 | E16: 1.6 | F16: 4 | G16: One enemy | H16: 0 | I16: 0.5 | J16: =INDEX($C$25:$C$44,D16) -> 22 | K16: =ROUND(J16*E16,0) -> 35 | L16: =ROUND($C$44*E16,0) -> 46 | M16: 1.6x hit, heals you for half the damage dealt
A17: Judgement | B17: J | C17: Damage | D17: 20 | E17: 4 | F17: 8 | G17: One enemy | H17: 0 | I17: - | J17: =INDEX($C$25:$C$44,D17) -> 29 | K17: =ROUND(J17*E17,0) -> 116 | L17: =ROUND($C$44*E17,0) -> 116 | M17: Ultimate: 4x attack
A19: Raw Effect = damage before the enemy's defence and the ±20% random roll (see the Damage Table tab for after-defence numbers).
A20: Heals use max HP at that level. Lifesteal heals 50% of the damage that actually lands.
A23: Paladin Stats by Level
A24: Level | B24: Max HP | C24: Attack | D24: Defence | E24: Damage Blocked by Defence | F24: XP to Next Level | G24: Total XP to Reach | H24: New Ability
A25: 1 | B25: =$C$6+(A25-1)*$F$6 -> 120 | C25: =$D$6+(A25-1)*$G$6 -> 10 | D25: =$E$6+(A25-1)*$H$6 -> 6 | E25: =1-100/(100+D25) -> 0.056603774 | F25: =IF(A25<$M$6,50*A25,"MAX") -> 50 | G25: =25*A25*(A25-1) -> 0 | H25: Starts with Shield Bash, Holy Strike
A26: 2 | B26: =$C$6+(A26-1)*$F$6 -> 132 | C26: =$D$6+(A26-1)*$G$6 -> 11 | D26: =$E$6+(A26-1)*$H$6 -> 9 | E26: =1-100/(100+D26) -> 0.082568807 | F26: =IF(A26<$M$6,50*A26,"MAX") -> 100 | G26: =25*A26*(A26-1) -> 50 | H26: =IFERROR(INDEX($A$11:$A$17,MATCH(A26,$D$11:$D$17,0)),"") -> Holy Ground
A27: 3 | B27: =$C$6+(A27-1)*$F$6 -> 144 | C27: =$D$6+(A27-1)*$G$6 -> 12 | D27: =$E$6+(A27-1)*$H$6 -> 12 | E27: =1-100/(100+D27) -> 0.10714286 | F27: =IF(A27<$M$6,50*A27,"MAX") -> 150 | G27: =25*A27*(A27-1) -> 150 | H27: =IFERROR(INDEX($A$11:$A$17,MATCH(A27,$D$11:$D$17,0)),"")
A28: 4 | B28: =$C$6+(A28-1)*$F$6 -> 156 | C28: =$D$6+(A28-1)*$G$6 -> 13 | D28: =$E$6+(A28-1)*$H$6 -> 15 | E28: =1-100/(100+D28) -> 0.13043478 | F28: =IF(A28<$M$6,50*A28,"MAX") -> 200 | G28: =25*A28*(A28-1) -> 300 | H28: =IFERROR(INDEX($A$11:$A$17,MATCH(A28,$D$11:$D$17,0)),"")
A29: 5 | B29: =$C$6+(A29-1)*$F$6 -> 168 | C29: =$D$6+(A29-1)*$G$6 -> 14 | D29: =$E$6+(A29-1)*$H$6 -> 18 | E29: =1-100/(100+D29) -> 0.15254237 | F29: =IF(A29<$M$6,50*A29,"MAX") -> 250 | G29: =25*A29*(A29-1) -> 500 | H29: =IFERROR(INDEX($A$11:$A$17,MATCH(A29,$D$11:$D$17,0)),"") -> Lay on Hands
A30: 6 | B30: =$C$6+(A30-1)*$F$6 -> 180 | C30: =$D$6+(A30-1)*$G$6 -> 15 | D30: =$E$6+(A30-1)*$H$6 -> 21 | E30: =1-100/(100+D30) -> 0.17355372 | F30: =IF(A30<$M$6,50*A30,"MAX") -> 300 | G30: =25*A30*(A30-1) -> 750 | H30: =IFERROR(INDEX($A$11:$A$17,MATCH(A30,$D$11:$D$17,0)),"")
A31: 7 | B31: =$C$6+(A31-1)*$F$6 -> 192 | C31: =$D$6+(A31-1)*$G$6 -> 16 | D31: =$E$6+(A31-1)*$H$6 -> 24 | E31: =1-100/(100+D31) -> 0.19354839 | F31: =IF(A31<$M$6,50*A31,"MAX") -> 350 | G31: =25*A31*(A31-1) -> 1050 | H31: =IFERROR(INDEX($A$11:$A$17,MATCH(A31,$D$11:$D$17,0)),"")
A32: 8 | B32: =$C$6+(A32-1)*$F$6 -> 204 | C32: =$D$6+(A32-1)*$G$6 -> 17 | D32: =$E$6+(A32-1)*$H$6 -> 27 | E32: =1-100/(100+D32) -> 0.21259843 | F32: =IF(A32<$M$6,50*A32,"MAX") -> 400 | G32: =25*A32*(A32-1) -> 1400 | H32: =IFERROR(INDEX($A$11:$A$17,MATCH(A32,$D$11:$D$17,0)),"")
A33: 9 | B33: =$C$6+(A33-1)*$F$6 -> 216 | C33: =$D$6+(A33-1)*$G$6 -> 18 | D33: =$E$6+(A33-1)*$H$6 -> 30 | E33: =1-100/(100+D33) -> 0.23076923 | F33: =IF(A33<$M$6,50*A33,"MAX") -> 450 | G33: =25*A33*(A33-1) -> 1800 | H33: =IFERROR(INDEX($A$11:$A$17,MATCH(A33,$D$11:$D$17,0)),"") -> Divine Aegis
A34: 10 | B34: =$C$6+(A34-1)*$F$6 -> 228 | C34: =$D$6+(A34-1)*$G$6 -> 19 | D34: =$E$6+(A34-1)*$H$6 -> 33 | E34: =1-100/(100+D34) -> 0.2481203 | F34: =IF(A34<$M$6,50*A34,"MAX") -> 500 | G34: =25*A34*(A34-1) -> 2250 | H34: =IFERROR(INDEX($A$11:$A$17,MATCH(A34,$D$11:$D$17,0)),"")
A35: 11 | B35: =$C$6+(A35-1)*$F$6 -> 240 | C35: =$D$6+(A35-1)*$G$6 -> 20 | D35: =$E$6+(A35-1)*$H$6 -> 36 | E35: =1-100/(100+D35) -> 0.26470588 | F35: =IF(A35<$M$6,50*A35,"MAX") -> 550 | G35: =25*A35*(A35-1) -> 2750 | H35: =IFERROR(INDEX($A$11:$A$17,MATCH(A35,$D$11:$D$17,0)),"")
A36: 12 | B36: =$C$6+(A36-1)*$F$6 -> 252 | C36: =$D$6+(A36-1)*$G$6 -> 21 | D36: =$E$6+(A36-1)*$H$6 -> 39 | E36: =1-100/(100+D36) -> 0.28057554 | F36: =IF(A36<$M$6,50*A36,"MAX") -> 600 | G36: =25*A36*(A36-1) -> 3300 | H36: =IFERROR(INDEX($A$11:$A$17,MATCH(A36,$D$11:$D$17,0)),"")
A37: 13 | B37: =$C$6+(A37-1)*$F$6 -> 264 | C37: =$D$6+(A37-1)*$G$6 -> 22 | D37: =$E$6+(A37-1)*$H$6 -> 42 | E37: =1-100/(100+D37) -> 0.29577465 | F37: =IF(A37<$M$6,50*A37,"MAX") -> 650 | G37: =25*A37*(A37-1) -> 3900 | H37: =IFERROR(INDEX($A$11:$A$17,MATCH(A37,$D$11:$D$17,0)),"") -> Radiant Slash
... A44: 20 | B44: =$C$6+(A44-1)*$F$6 -> 348 | C44: =$D$6+(A44-1)*$G$6 -> 29 | D44: =$E$6+(A44-1)*$H$6 -> 63 | E44: =1-100/(100+D44) -> 0.38650307 | F44: =IF(A44<$M$6,50*A44,"MAX") -> MAX | G44: =25*A44*(A44-1) -> 9500 | H44: =IFERROR(INDEX($A$11:$A$17,MATCH(A44,$D$11:$D$17,0)),"") -> Judgement
A46: XP to Next Level = 50 x level (from xp_needed() in player.py). Levelling up fully heals you.

Sheet Dungeon Plans
A1: Severance - Dungeon Plans
A2: Build steps are on the Build Order tab. Plans from the GameNotes vault (Dungeons & Enemies.md) next to what's actually built in the text prototype. Green = done, yellow = partly done / idea, red = not started.
A4: Overview
A5: # | B5: Dungeon | C5: Layout | D5: Theme / Enemies | E5: Target Time | F5: Target Level | G5: Difficulty | H5: Bosses | I5: Special Features | J5: Loot | K5: Status | L5: Built So Far | M5: Still To Do
A6: 1 | B6: Rainforest River | C6: Straight path | D6: Along a river. Slightly mutated normal animals (Tadpole, Frog, Boar) | E6: 5-10 mins | F6: Lv 1 | G6: Easy. Teaches the basics of dungeons and your class | H6: Mutated Cheetah | I6: Tutorial: teaches the basics | J6: XP only | K6: Partly done | L6: 4 rooms + boss. Smart player ~87% win, casual ~65% | M6: Tutorial tips per room. Check run length (probably ~3-5 mins now)
A7: 2 | B7: Derelict Spaceship | C7: Branching paths | D7: Spaceship. Robots and drones (Drone, Maintenance Bot, Turret) | E7: ~10 mins | F7: Lv 2-4 | G7: Medium | H7: 3 final bosses, one per path: Tank, DPS, Summoner | I7: Player picks a path. Each boss matches a class type | J7: Bonus loot for the class that matches the boss | K7: Partly done | L7: Straight path, 4 rooms, 1 boss (Rogue Overseer = fits DPS?). Smart 92% / casual 62% at Lv 2 | M7: Path choice, 2 more bosses, Summoner boss mechanic, loot system
A8: 3 | B8: Cave | C8: Floors | D8: TBD - deeper floors, harder enemies | E8: 20-25 mins | F8: TBD (big power spike) | G8: Hard | H8: Main boss at the bottom + a 'recon clone' at the end of each floor | I8: Clones are copies of the main boss sent to scout: they fight back but do little damage | J8: TBD | K8: Not started | L8: - | M8: Floors in dungeon(), cave enemies, clone recipes, main boss, sims
A9: - | B9: Outpost (between dungeons) | C9: Hub | D9: Dungeon outpost / fortified camp from the lore. Wandering traders, NPCs | E9: - | F9: - | G9: Safe zone | H9: - | I9: Shops + talking to NPCs between dungeons | J9: Buy items (e.g. potions) with gold | K9: Not started | L9: - | M9: Gold drops, shop menu, NPC dialogue, items/inventory
A11: Room by Room
A12: # | B12: Dungeon | C12: Section | D12: Room | E12: Enemies | F12: XP | G12: Tip / Notes | K12: Status
A13: 1 | B13: Rainforest River | C13: Path | D13: 1 | E13: Tadpole x2 | F13: 10 | G13: Tip idea: how to attack / use abilities | K13: Built
A14: 1 | B14: Rainforest River | C14: Path | D14: 2 | E14: Frog x2 | F14: 16 | G14: Tip idea: cooldowns | K14: Built
A15: 1 | B15: Rainforest River | C15: Path | D15: 3 | E15: Boar + Frog | F15: 20 | G15: Tip idea: kill the Boar first (hits hard, low defence) | K15: Built
A16: 1 | B16: Rainforest River | C16: Boss | D16: 4 | E16: Mutated Cheetah | F16: 30 | G16: Tip idea: bosses warn you, press D to defend. XP before boss must stay under 50 (now 46) | K16: Built
A17: 2 | B17: Derelict Spaceship | C17: Shared start | D17: 1 | E17: Security Drone x3 | F17: 18 | K17: Built
A18: 2 | B18: Derelict Spaceship | C18: Shared start | D18: 2 | E18: Maintenance Bot + Drone x2 | F18: 28 | K18: Built
A19: 2 | B19: Derelict Spaceship | C19: Shared start | D19: 3 | E19: Sentry Turret x2 | F19: 28 | G19: Could become the split point | K19: Built
A20: 2 | B20: Derelict Spaceship | C20: Path A - Tank | D20: Boss | E20: Tank boss (TBD) | F20: - | G20: High HP / defence. Bonus loot for Tanks (e.g. Paladin) | K20: Planned
A21: 2 | B21: Derelict Spaceship | C21: Path B - DPS | D21: Boss | E21: Rogue Overseer? | F21: 45 | G21: Current boss could be the DPS one. Bonus loot for DPS (e.g. Sorcerer) | K21: Idea
A22: 2 | B22: Derelict Spaceship | C22: Path C - Summoner | D22: Boss | E22: Summoner boss (TBD) | F22: - | G22: Calls in adds mid-fight (new mechanic). Bonus loot for Summoners (e.g. Chimera) | K22: Planned
A23: 3 | B23: Cave | C23: Floor 1 | D23: Rooms | E23: TBD | F23: - | K23: Planned
A24: 3 | B24: Cave | C24: Floor 1 | D24: End | E24: Recon Clone 1 | F24: - | G24: Weak copy of the main boss | K24: Planned
A25: 3 | B25: Cave | C25: Floor 2 | D25: Rooms | E25: TBD | F25: - | G25: Harder than floor 1 | K25: Planned
A26: 3 | B26: Cave | C26: Floor 2 | D26: End | E26: Recon Clone 2 | F26: - | K26: Planned
A27: 3 | B27: Cave | C27: Floor 3 | D27: Rooms | E27: TBD | F27: - | G27: Number of floors TBD | K27: Planned
A28: 3 | B28: Cave | C28: Bottom | D28: Boss | E28: Main boss (TBD) | F28: - | G28: The real one | K28: Planned
A30: Design Rules (from your notes)
A31: • No 2 dungeons should be exactly the same (similar is fine).
A32: • Every dungeon ends with a boss fight, sometimes with a lore reveal.
A33: • Every boss gives gear + XP. Gear: pillar set (higher drop rate) and subclass set (lower drop rate), starting in Dungeon 2.
A34: • XP: normal enemies give a little XP, bosses give a big XP drop. (Prototype is the other way round right now: Rainforest adds give 46, boss gives 30.)
A35: • Between dungeons: an outpost hub with shops and NPCs to talk to.
A36: • Dungeons get longer and harder as the god gets angrier (early 5-10 mins, later 30+).
A37: • Prototype max level is 20 (the full game plan is 1-50).
A38: • Balance rule: a dungeon built for level L should give about 1.2 x 50 x L XP for a full clear.
A40: XP Plan (suggested - not in the code yet)
B41: Enemy | C41: Dungeon | D41: XP Now | E41: XP Suggested
B42: Mutated Tadpole | C42: Rainforest | D42: 5 | E42: 2
B43: Mutated Frog | C43: Rainforest | D43: 8 | E43: 3
B44: Mutated Boar | C44: Rainforest | D44: 12 | E44: 4
...

Sheet Build Order
A1: Severance - Build Order
A2: Top to bottom = the order to build in. Change Status as you go (Done / In progress / Not started / Undecided). Filter the Area column to see one part.
A4: Step | B4: What | C4: Area | D4: Who | E4: Size | F4: Needs Step | G4: Notes | H4: Status
A5: 1 | B5: Mana system (cost, can_afford, regen) | C5: Sorcerer | D5: You | E5: Small | F5: - | G5: Abilities can cost mana, checked in battle | H5: Done
A6: 2 | B6: Automated tests (pytest) | C6: All | D6: You | E6: Small | F6: - | G6: 8 tests: damage, blocking, healing, level-up stats, ability unlock, cooldowns. Run with: pytest -v | H6: Done
A7: 3 | B7: Mana bar | C7: Sorcerer | D7: You | E7: Small | F7: 1 | G7: show_mana_bar in player.py, show MP cost in the menu | H7: Not started
A8: 4 | B8: Sorcerer class + Mana Tide | C8: Sorcerer | D8: You | E8: Medium | F8: 3 | G8: Add to class select. Add tests: can't cast without mana, regen caps at max | H8: Not started
A9: 5 | B9: Sorcerer balance sims | C9: Sorcerer | D9: Me | E9: Small | F9: 4 | G9: Tune stats + mana costs | H9: Not started
A10: 6 | B10: Tutorial tips per room | C10: Rainforest | D10: You | E10: Small | F10: - | G10: tips dict, print in dungeon() | H10: Not started
A11: 7 | B11: XP rework: small XP from enemies, big from bosses | C11: All dungeons | D11: Me | E11: Small | F11: - | G11: Numbers only. Suggested split is on Dungeon Plans | H11: Not started
A12: 8 | B12: Cheetah Growl (stun) | C12: Rainforest | D12: You (mechanic) + me (numbers) | E12: Small | F12: - | G12: stunned flag, Move effect, skip turn. No damage vs 0.5x hit undecided | H12: Undecided
A13: 9 | B13: Floors + recon clones | C13: Cave | D13: You (floors) + me (enemies, sims) | E13: Medium | F13: - | G13: A floor = a group of rooms. Clones = weaker boss recipes | H13: Not started
A14: 10 | B14: Path choice | C14: Spaceship | D14: You | E14: Medium | F14: - | G14: Player picks a route after the shared rooms | H14: Not started
A15: 11 | B15: Summoner boss | C15: Spaceship | D15: You (mechanic) + me (stats) | E15: Medium | F15: 10 | G15: Boss adds enemies to the fight mid-battle | H15: Not started
A16: 12 | B16: Loot / gear | C16: All | D16: You | E16: Large | F16: - | G16: Pillar set (common) + subclass set (rare) from Dungeon 2 on. Bonus loot per Spaceship path | H16: Not started
... A20: 16 | B20: Polish: colours + ASCII art | C20: All | D20: You | E20: Medium | F20: - | G20: From the Text Prototype build plan (colorama) | H20: Not started

Sheet Base Moves
A1: Moves every enemy can use (Enemy.take_turn in enemy.py)
A2: Bosses try their special moves first; if none trigger, they roll on this table.
A4: Move | B4: Chance % | C4: Power (x Attack) | D4: Hits | E4: Warning? | F4: What it does
A5: Attack | B5: 0.5 | C5: 1 | D5: 1 | E5: No | F5: Normal hit.
A6: Brace | B6: 0.2 | C6: 0 | D6: 0 | E6: No | F6: Takes 1/1.5 damage until its next turn (defending_power 1.5).
A7: Heavy Attack | B7: 0.2 | C7: 1.5 | D7: 1 | E7: No | F7: Big hit.
A8: Charge Up | B8: 0.1 | C8: 0 | D8: 0 | E8: Yes: "charges up..." | F8: Does nothing this turn, then next turn unleashes Devastating Attack.
A9: Devastating Attack | B9: - | C9: 2.2 | D9: 1 | E9: (follows Charge Up) | F9: Always happens the turn after Charge Up. Defend to reduce it.
A11: Total chance | B11: =SUM(B5:B8) -> 1

Sheet Boss Specials
A1: Boss special moves (Move objects in enemies.py)
A2: Raw damage is before the player's defence and the +/-20% variance. Warned moves land the turn AFTER the warning.
A4: Boss | B4: Move | C4: Chance % | D4: Power (x Attack) | E4: Hits | F4: Total Power | G4: Boss Attack | H4: Raw Damage | I4: Raw Damage (Enraged) | J4: Warning Text
A5: Mutated Cheetah | B5: Pounce | C5: 0.25 | D5: 1.25 | E5: 2 | F5: =D5*E5 -> 2.5 | G5: =INDEX(Monsters!$F$5:$F$17,MATCH(A5,Monsters!$A$5:$A$17,0)) -> 12 | H5: =ROUND(G5*F5,0) -> 30 | I5: =ROUND(INDEX(Monsters!$M$5:$M$17,MATCH(A5,Monsters!$A$5:$A$17,0))*F5,0) -> 60 | J5: crouches low, ready to pounce!
A6: Rogue Overseer | B6: Laser Sweep | C6: 0.2 | D6: 2.25 | E6: 1 | F6: =D6*E6 -> 2.25 | G6: =INDEX(Monsters!$F$5:$F$17,MATCH(A6,Monsters!$A$5:$A$17,0)) -> 10 | H6: =ROUND(G6*F6,0) -> 23 | I6: =ROUND(INDEX(Monsters!$M$5:$M$17,MATCH(A6,Monsters!$A$5:$A$17,0))*F6,0) -> 34 | J6: locks its targeting laser onto you!
A7: Rogue Overseer | B7: Twin Blasters | C7: 0.15 | D7: 0.8 | E7: 2 | F7: =D7*E7 -> 1.6 | G7: =INDEX(Monsters!$F$5:$F$17,MATCH(A7,Monsters!$A$5:$A$17,0)) -> 10 | H7: =ROUND(G7*F7,0) -> 16 | I7: =ROUND(INDEX(Monsters!$M$5:$M$17,MATCH(A7,Monsters!$A$5:$A$17,0))*F7,0) -> 24 | J7: (none - instant)
A8: Rift Warden | B8: Crushing Slam | C8: 0.2 | D8: 2.5 | E8: 1 | F8: =D8*E8 -> 2.5 | G8: =INDEX(Monsters!$F$5:$F$17,MATCH(A8,Monsters!$A$5:$A$17,0)) -> 34 | H8: =ROUND(G8*F8,0) -> 85 | I8: =ROUND(INDEX(Monsters!$M$5:$M$17,MATCH(A8,Monsters!$A$5:$A$17,0))*F8,0) -> 119 | J8: raises its hammer high above you!
A9: Hollow Colossus | B9: Cataclysm | C9: 0.15 | D9: 3 | E9: 1 | F9: =D9*E9 -> 3 | G9: =INDEX(Monsters!$F$5:$F$17,MATCH(A9,Monsters!$A$5:$A$17,0)) -> 42 | H9: =ROUND(G9*F9,0) -> 126 | I9: =ROUND(INDEX(Monsters!$M$5:$M$17,MATCH(A9,Monsters!$A$5:$A$17,0))*F9,0) -> 189 | J9: draws the rift into its fists...
A10: Hollow Colossus | B10: Rending Claws | C10: 0.15 | D10: 0.9 | E10: 2 | F10: =D10*E10 -> 1.8 | G10: =INDEX(Monsters!$F$5:$F$17,MATCH(A10,Monsters!$A$5:$A$17,0)) -> 42 | H10: =ROUND(G10*F10,0) -> 76 | I10: =ROUND(INDEX(Monsters!$M$5:$M$17,MATCH(A10,Monsters!$A$5:$A$17,0))*F10,0) -> 113 | J10: (none - instant)
A11: Hollow Colossus | B11: Tremor | C11: 0.1 | D11: 1.4 | E11: 1 | F11: =D11*E11 -> 1.4 | G11: =INDEX(Monsters!$F$5:$F$17,MATCH(A11,Monsters!$A$5:$A$17,0)) -> 42 | H11: =ROUND(G11*F11,0) -> 59 | I11: =ROUND(INDEX(Monsters!$M$5:$M$17,MATCH(A11,Monsters!$A$5:$A$17,0))*F11,0) -> 88 | J11: stamps the ground and the floor starts to crack!
A13: Green = pulled from the Monsters sheet.

Sheet Damage Table
A1: Raw damage of every enemy move
A2: Attack x move power. Change an Attack value on the Monsters sheet and this updates.
A4: Name | B4: Attack | C4: Attack (1.0x) | D4: Heavy Attack (1.5x) | E4: Devastating (2.2x) | F4: Enraged Attack | G4: Enraged Heavy | H4: Enraged Devastating
A5: =Monsters!A5 -> Mutated Tadpole | B5: =Monsters!F5 -> 4 | C5: =ROUND(B5*'Base Moves'!$C$5,0) -> 4 | D5: =ROUND(B5*'Base Moves'!$C$7,0) -> 6 | E5: =ROUND(B5*'Base Moves'!$C$9,0) -> 9 | F5: =IF(Monsters!D5="Boss",ROUND(Monsters!M5,0),"-") -> - | G5: =IF(Monsters!D5="Boss",ROUND(Monsters!M5*'Base Moves'!$C$7,0),"-") -> - | H5: =IF(Monsters!D5="Boss",ROUND(Monsters!M5*'Base Moves'!$C$9,0),"-") -> -
A6: =Monsters!A6 -> Mutated Frog | B6: =Monsters!F6 -> 4 | C6: =ROUND(B6*'Base Moves'!$C$5,0) -> 4 | D6: =ROUND(B6*'Base Moves'!$C$7,0) -> 6 | E6: =ROUND(B6*'Base Moves'!$C$9,0) -> 9 | F6: =IF(Monsters!D6="Boss",ROUND(Monsters!M6,0),"-") -> - | G6: =IF(Monsters!D6="Boss",ROUND(Monsters!M6*'Base Moves'!$C$7,0),"-") -> - | H6: =IF(Monsters!D6="Boss",ROUND(Monsters!M6*'Base Moves'!$C$9,0),"-") -> -
A7: =Monsters!A7 -> Mutated Boar | B7: =Monsters!F7 -> 12 | C7: =ROUND(B7*'Base Moves'!$C$5,0) -> 12 | D7: =ROUND(B7*'Base Moves'!$C$7,0) -> 18 | E7: =ROUND(B7*'Base Moves'!$C$9,0) -> 26 | F7: =IF(Monsters!D7="Boss",ROUND(Monsters!M7,0),"-") -> - | G7: =IF(Monsters!D7="Boss",ROUND(Monsters!M7*'Base Moves'!$C$7,0),"-") -> - | H7: =IF(Monsters!D7="Boss",ROUND(Monsters!M7*'Base Moves'!$C$9,0),"-") -> -
A8: =Monsters!A8 -> Mutated Cheetah | B8: =Monsters!F8 -> 12 | C8: =ROUND(B8*'Base Moves'!$C$5,0) -> 12 | D8: =ROUND(B8*'Base Moves'!$C$7,0) -> 18 | E8: =ROUND(B8*'Base Moves'!$C$9,0) -> 26 | F8: =IF(Monsters!D8="Boss",ROUND(Monsters!M8,0),"-") -> 24 | G8: =IF(Monsters!D8="Boss",ROUND(Monsters!M8*'Base Moves'!$C$7,0),"-") -> 36 | H8: =IF(Monsters!D8="Boss",ROUND(Monsters!M8*'Base Moves'!$C$9,0),"-") -> 53
A9: =Monsters!A9 -> Security Drone | B9: =Monsters!F9 -> 5 | C9: =ROUND(B9*'Base Moves'!$C$5,0) -> 5 | D9: =ROUND(B9*'Base Moves'!$C$7,0) -> 8 | E9: =ROUND(B9*'Base Moves'!$C$9,0) -> 11 | F9: =IF(Monsters!D9="Boss",ROUND(Monsters!M9,0),"-") -> - | G9: =IF(Monsters!D9="Boss",ROUND(Monsters!M9*'Base Moves'!$C$7,0),"-") -> - | H9: =IF(Monsters!D9="Boss",ROUND(Monsters!M9*'Base Moves'!$C$9,0),"-") -> -
A10: =Monsters!A10 -> Maintenance Bot | B10: =Monsters!F10 -> 8 | C10: =ROUND(B10*'Base Moves'!$C$5,0) -> 8 | D10: =ROUND(B10*'Base Moves'!$C$7,0) -> 12 | E10: =ROUND(B10*'Base Moves'!$C$9,0) -> 18 | F10: =IF(Monsters!D10="Boss",ROUND(Monsters!M10,0),"-") -> - | G10: =IF(Monsters!D10="Boss",ROUND(Monsters!M10*'Base Moves'!$C$7,0),"-") -> - | H10: =IF(Monsters!D10="Boss",ROUND(Monsters!M10*'Base Moves'!$C$9,0),"-") -> -
A11: =Monsters!A11 -> Sentry Turret | B11: =Monsters!F11 -> 9 | C11: =ROUND(B11*'Base Moves'!$C$5,0) -> 9 | D11: =ROUND(B11*'Base Moves'!$C$7,0) -> 14 | E11: =ROUND(B11*'Base Moves'!$C$9,0) -> 20 | F11: =IF(Monsters!D11="Boss",ROUND(Monsters!M11,0),"-") -> - | G11: =IF(Monsters!D11="Boss",ROUND(Monsters!M11*'Base Moves'!$C$7,0),"-") -> - | H11: =IF(Monsters!D11="Boss",ROUND(Monsters!M11*'Base Moves'!$C$9,0),"-") -> -
A12: =Monsters!A12 -> Rogue Overseer | B12: =Monsters!F12 -> 10 | C12: =ROUND(B12*'Base Moves'!$C$5,0) -> 10 | D12: =ROUND(B12*'Base Moves'!$C$7,0) -> 15 | E12: =ROUND(B12*'Base Moves'!$C$9,0) -> 22 | F12: =IF(Monsters!D12="Boss",ROUND(Monsters!M12,0),"-") -> 15 | G12: =IF(Monsters!D12="Boss",ROUND(Monsters!M12*'Base Moves'!$C$7,0),"-") -> 23 | H12: =IF(Monsters!D12="Boss",ROUND(Monsters!M12*'Base Moves'!$C$9,0),"-") -> 33
A13: =Monsters!A13 -> Rift Wisp | B13: =Monsters!F13 -> 18 | C13: =ROUND(B13*'Base Moves'!$C$5,0) -> 18 | D13: =ROUND(B13*'Base Moves'!$C$7,0) -> 27 | E13: =ROUND(B13*'Base Moves'!$C$9,0) -> 40 | F13: =IF(Monsters!D13="Boss",ROUND(Monsters!M13,0),"-") -> - | G13: =IF(Monsters!D13="Boss",ROUND(Monsters!M13*'Base Moves'!$C$7,0),"-") -> - | H13: =IF(Monsters!D13="Boss",ROUND(Monsters!M13*'Base Moves'!$C$9,0),"-") -> -
A14: =Monsters!A14 -> Rift Knight | B14: =Monsters!F14 -> 32 | C14: =ROUND(B14*'Base Moves'!$C$5,0) -> 32 | D14: =ROUND(B14*'Base Moves'!$C$7,0) -> 48 | E14: =ROUND(B14*'Base Moves'!$C$9,0) -> 70 | F14: =IF(Monsters!D14="Boss",ROUND(Monsters!M14,0),"-") -> - | G14: =IF(Monsters!D14="Boss",ROUND(Monsters!M14*'Base Moves'!$C$7,0),"-") -> - | H14: =IF(Monsters!D14="Boss",ROUND(Monsters!M14*'Base Moves'!$C$9,0),"-") -> -
A15: =Monsters!A15 -> Rift Stalker | B15: =Monsters!F15 -> 35 | C15: =ROUND(B15*'Base Moves'!$C$5,0) -> 35 | D15: =ROUND(B15*'Base Moves'!$C$7,0) -> 53 | E15: =ROUND(B15*'Base Moves'!$C$9,0) -> 77 | F15: =IF(Monsters!D15="Boss",ROUND(Monsters!M15,0),"-") -> - | G15: =IF(Monsters!D15="Boss",ROUND(Monsters!M15*'Base Moves'!$C$7,0),"-") -> - | H15: =IF(Monsters!D15="Boss",ROUND(Monsters!M15*'Base Moves'!$C$9,0),"-") -> -
A16: =Monsters!A16 -> Rift Warden | B16: =Monsters!F16 -> 34 | C16: =ROUND(B16*'Base Moves'!$C$5,0) -> 34 | D16: =ROUND(B16*'Base Moves'!$C$7,0) -> 51 | E16: =ROUND(B16*'Base Moves'!$C$9,0) -> 75 | F16: =IF(Monsters!D16="Boss",ROUND(Monsters!M16,0),"-") -> 48 | G16: =IF(Monsters!D16="Boss",ROUND(Monsters!M16*'Base Moves'!$C$7,0),"-") -> 71 | H16: =IF(Monsters!D16="Boss",ROUND(Monsters!M16*'Base Moves'!$C$9,0),"-") -> 105
A17: =Monsters!A17 -> Hollow Colossus | B17: =Monsters!F17 -> 42 | C17: =ROUND(B17*'Base Moves'!$C$5,0) -> 42 | D17: =ROUND(B17*'Base Moves'!$C$7,0) -> 63 | E17: =ROUND(B17*'Base Moves'!$C$9,0) -> 92 | F17: =IF(Monsters!D17="Boss",ROUND(Monsters!M17,0),"-") -> 63 | G17: =IF(Monsters!D17="Boss",ROUND(Monsters!M17*'Base Moves'!$C$7,0),"-") -> 95 | H17: =IF(Monsters!D17="Boss",ROUND(Monsters!M17*'Base Moves'!$C$9,0),"-") -> 139

Sheet Balance Log
A1: Balance Log
A2: One row per change, oldest first. Add new changes at the bottom: date, what, old, new, why, and how you found out (sim or playtest).
A4: Date | B4: Area | C4: What Changed | D4: Old | E4: New | F4: Why | G4: Found By
A5: 28 Sep 2026 | B5: Combat | C5: Damage variance | D5: None (fixed damage) | E5: ±20% random | F5: Fights felt samey; percentage scales with stronger enemies | G5: Design
A6: 28 Sep 2026 | B6: Paladin | C6: Defend | D6: +2 defence (stacked forever) | E6: Damage ÷ 1.5 for one hit | F6: Old version stacked every turn and barely did anything | G6: Playtest
A7: 29 Sep 2026 | B7: Levelling | C7: XP needed per level | D7: - | E7: 24 × level | F7: First level system | G7: Design
A8: 29 Sep 2026 | B8: Paladin | C8: Level-up growth | D8: - | E8: +12 HP, +1 Atk, +3 Def | F8: Paladin is the tank: health and defence over damage | G8: Design
A9: 29 Sep 2026 | B9: Rainforest | C9: First dungeon stats | D9: - | E9: Frog 35/3/4, Boar 40/8/2, Cheetah 85/10/5 | F9: First version of the Rainforest | G9: Design
A10: 30 Sep 2026 | B10: Rainforest | C10: Mutated Frog (HP/Atk/Def) | D10: 35 / 3 / 4 | E10: 40 / 4 / 10 | F10: Even button-mashing cleared 100% of runs | G10: Simulation
A11: 30 Sep 2026 | B11: Rainforest | C11: Mutated Boar (HP/Atk/Def) | D11: 40 / 8 / 2 | E11: 35 / 12 / 2 | F11: Made it a fragile, hard-hitting threat | G11: Simulation
A12: 30 Sep 2026 | B12: Rainforest | C12: Mutated Cheetah (HP/Atk/XP) | D12: 85 / 10 / 25 | E12: 100 / 11 / 30 | F12: Boss was too easy | G12: Simulation
A13: 30 Sep 2026 | B13: Levelling | C13: XP needed per level | D13: 24 × level | E13: 50 × level | F13: Levelling before the boss gave a full heal and removed all tension | G13: Simulation
A14: 30 Sep 2026 | B14: Dungeons | C14: Rest between rooms | D14: No healing | E14: Heal 25–35% of max HP | F14: Without it, rooms drained one HP pool and the boss was unwinnable | G14: Simulation
A15: 30 Sep 2026 | B15: Paladin | C15: Defend strength (defending_power) | D15: ÷ 1.5 | E15: ÷ 3 | F15: Defending against warnings made you MORE likely to lose | G15: Simulation
... A30: 1 Oct 2026 | B30: Rainforest | C30: New Room 1 | D30: Starts with Frogs | E30: 2 Tadpoles first | F30: Longer dungeon, same difficulty (2 keeps XP under the Lv 2 trap) | G30: Simulation
